Workbook

Sheet SUMMARY
A23: ="Geleneksel taşıma yöntemleri yerine intermodal taşımacılığı tercih ederek "&TEXT(ROUND(CALCULATION!AF5,0),"#.##")&" adet yetişkin kızılçam ağacı (yaklaşık 0,70 hektar orman) kurtardınız." -> Geleneksel taşıma yöntemleri yerine intermodal taşımacılığı tercih ederek 287 adet yetişkin kızılçam ağacı (yaklaşık 0,70 hektar orman) kurtardınız.
A24: ="By choosing intermodal transportation instead of traditional transportation methods, you have saved "&TEXT(ROUND(CALCULATION!AF5,0),"#.##")&" adult red pine trees (0,70 hectares of forest approximately)." -> By choosing intermodal transportation instead of traditional transportation methods, you have saved 287 adult red pine trees (0,70 hectares of forest approximately).
A27: ROUTE BASED SAVED EMISSIONS
E28: *
A29: Loading Country | B29: Loading City | C29: Unloading Country | D29: Unloading City | E29: Shipments | F29: Total Intermodal CO2 Emissions | G29: Total Road CO2 Emissions | H29: Saved CO2 Emissions (kg CO2)
A30: TURKEY | B30: İZMİR | C30: SWITZERLAND | D30: 1425 | F30: 3424.35 | G30: 7739.16 | H30: 4314.81
A31: Genel Toplam | F31: 3424.35 | G31: 7739.16 | H31: 4314.81

Sheet CALCULATION
B2: TOTAL CO2 EMISSIONS | AE2: Saved Tree (Avg.) | AF2: Saved Pinus Brutia (Turkish Pine)
B4: CO2 total SHIP (ton CO2) | C4: CO2 total RAIL (ton CO2) | D4: CO2 total ROAD (ton CO2) | E4: CO2 total (ton CO2) | F4: CO2 total Full Road Route (ton CO2) | G4: Saved CO2 (ton CO2) | AE4: 22.5 | AF4: 411.4
B5: =SUM(AD10:AD39)/1000 -> 12.92976 | C5: =SUM(AE10:AE39)/1000 -> 1.75104 | D5: =SUM(AF10:AF39)/1000 -> 34.60842 | E5: =SUM(B5:D5) -> 49.28922 | F5: =SUM(AH10:AH39)/1000 -> 167.35171 | G5: =SUM(AI10:AI39)/1000 -> 118.06249 | AE5: =G5*1000/AE4 -> 5247.2219 | AF5: =G5*1000/AF4 -> 286.97737
V6: 0.121 | W6: 0.012 | X6: 0.016 | AE6: =AE5/1600 -> 3.2795137 | AF6: =AF5/1600 -> 0.17936086
A7: Information About Shipment | P7: Distance multi-modal transport | U7: Distance only road transport | V7: CO2 emission factor (kg CO2/tonkm) | Y7: CO2 emission
A8: Fill in | B8: Fill in | C8: Fill in | D8: Fill in | E8: Fill in | F8: Fill in | G8: Fill in | H8: Fill in | K8: Fill in | M8: Fill in | N8: Fill in | O8: Fill in | Q8: Fill in | R8: Fill in | S8: Fill in | T8: Fill in | U8: Standard value | V8: Standard value | W8: Standard value | X8: Calculated | Y8: Calculated | Z8: Calculated | AA8: Calculated | AB8: Calculated | AC8: Calculated | AD8: Calculated | AE8: Calculated | AF8: Calculated | AG8: Calculated | AH8: Calculated
A9: # | B9: Referance Number (Carrier) | C9: Export / Import | D9: Carrier | E9: Loading Country | F9: Loading City | G9: Unloading Country | H9: Unloading City | I9: Route | J9: Route Detail | K9: Taşıma Modu | L9: Realized date of loading | M9: Realized date of unloading | N9: Vehicle type- Container TEU | O9: Tonnage transported | P9: Pre-carriage ROAD (km) | Q9: Pre-carriage ROAD (km, if electric) | R9: Main carriage SHIP (km) | S9: Main carriage RAIL (km) | T9: On-carriage ROAD (km) | U9: Main carriage ROAD (km) | V9: ROAD 0,121 | W9: SHIP 0,012 | X9: RAIL 0,016 | Y9: Pre-carriage ROAD (kg CO2) | Z9: Main carriage SHIP (kg CO2) | AA9: Main carriage RAIL (kg CO2) | AB9: On-carriage ROAD (kg CO2) | AC9: Main carriage ROAD (kg CO2) | AD9: Total SHIP (kg CO2) | AE9: Total RAIL (kg CO2) | AF9: Total ROAD (kg CO2) | AG9: Total (kg CO2) | AH9: *If Full Road (kg CO2) | AI9: Saved Emissions (kg CO2)
A10: 1 | C10: EXPORT | D10: SARP INTERMODAL | E10: TURKEY | F10: KOCAELİ | G10: DE | H10: 50829 | I10: PENDIK (TR) - TRIESTE (IT) - DUISBURG (DE)-TURKEY-KOCAELİ-DE-50829 | J10: PENDIK (TR) - TRIESTE (IT) - DUISBURG (DE) | K10: =VLOOKUP(CO2_Calculator_Table[[#This Row],[Referance Number (Carrier)]],#REF!,10,0) -> #REF! | L10: =VLOOKUP(CO2_Calculator_Table[[#This Row],[Referance Number (Carrier)]],#REF!,14,0) -> #REF! | M10: =VLOOKUP(CO2_Calculator_Table[[#This Row],[Referance Number (Carrier)]],#REF!,15,0) -> #REF! | N10: 24TON / 45HCPW BOX | O10: 24 | P10: =SUMIFS(ROUTES!H:H,ROUTES!B:B,CO2_Calculator_Table[[#This Row],[Route]],ROUTES!E:E,CO2_Calculator_Table[[#This Row],[Loading City]],ROUTES!G:G,CO2_Calculator_Table[[#This Row],[Unloading City]],ROUTES!C:C,CO2_Calculator_Table[[#This Row],[Route Detail]]) -> 20 | Q10: 0 | R10: =SUMIFS(ROUTES!I:I,ROUTES!B:B,CO2_Calculator_Table[[#This Row],[Route]],ROUTES!E:E,CO2_Calculator_Table[[#This Row],[Loading City]],ROUTES!G:G,CO2_Calculator_Table[[#This Row],[Unloading City]],ROUTES!C:C,CO2_Calculator_Table[[#This Row],[Route Detail]]) -> 2500 | S10: =SUMIFS(ROUTES!J:J,ROUTES!B:B,CO2_Calculator_Table[[#This Row],[Route]],ROUTES!E:E,CO2_Calculator_Table[[#This Row],[Loading City]],ROUTES!G:G,CO2_Calculator_Table[[#This Row],[Unloading City]],ROUTES!C:C,CO2_Calculator_Table[[#This Row],[Route Detail]]) -> 990 | T10: =SUMIFS(ROUTES!K:K,ROUTES!B:B,CO2_Calculator_Table[[#This Row],[Route]],ROUTES!E:E,CO2_Calculator_Table[[#This Row],[Loading City]],ROUTES!G:G,CO2_Calculator_Table[[#This Row],[Unloading City]],ROUTES!C:C,CO2_Calculator_Table[[#This Row],[Route Detail]]) -> 70 | U10: =SUMIFS(ROUTES!L:L,ROUTES!B:B,CO2_Calculator_Table[[#This Row],[Route]],ROUTES!E:E,CO2_Calculator_Table[[#This Row],[Loading City]],ROUTES!G:G,CO2_Calculator_Table[[#This Row],[Unloading City]],ROUTES!C:C,CO2_Calculator_Table[[#This Row],[Route Detail]]) -> 2555 | V10: =$V$6 -> 0.121 | W10: =$W$6 -> 0.012 | X10: =$X$6 -> 0.016 | Y10: =IF(CO2_Calculator_Table[[#This Row],[Pre-carriage ROAD (km, if electric)]]=0,(O10*P10*V10),(O10*Q10*V10)) -> 58.08 | Z10: =O10*R10*W10 -> 720 | AA10: =O10*S10*X10 -> 380.16 | AB10: =O10*T10*V10 -> 203.28 | AC10: =O10*U10*V10 -> 7419.72 | AD10: =Z10 -> 720 | AE10: =AA10 -> 380.16 | AF10: =Y10+AB10 -> 261.36 | AG10: =AD10+AE10+AF10 -> 1361.52 | AH10: =SUM(U10)*V10*O10 -> 7419.72 | AI10: =AH10-AG10 -> 6058.2
A11: 1 | C11: EXPORT | D11: SARP INTERMODAL | E11: TURKEY | F11: KOCAELİ | G11: GR | H11: 19300 | I11: PENDIK (TR) - PATRAS (GR)-TURKEY-KOCAELİ-GR-19300 | J11: PENDIK (TR) - PATRAS (GR) | K11: =VLOOKUP(CO2_Calculator_Table[[#This Row],[Referance Number (Carrier)]],#REF!,10,0) -> #REF! | L11: =VLOOKUP(CO2_Calculator_Table[[#This Row],[Referance Number (Carrier)]],#REF!,14,0) -> #REF! | M11: =VLOOKUP(CO2_Calculator_Table[[#This Row],[Referance Number (Carrier)]],#REF!,15,0) -> #REF! | N11: 24TON / 45HCPW BOX | O11: 24 | P11: =SUMIFS(ROUTES!H:H,ROUTES!B:B,CO2_Calculator_Table[[#This Row],[Route]],ROUTES!E:E,CO2_Calculator_Table[[#This Row],[Loading City]],ROUTES!G:G,CO2_Calculator_Table[[#This Row],[Unloading City]],ROUTES!C:C,CO2_Calculator_Table[[#This Row],[Route Detail]]) -> 20 | Q11: 0 | R11: =SUMIFS(ROUTES!I:I,ROUTES!B:B,CO2_Calculator_Table[[#This Row],[Route]],ROUTES!E:E,CO2_Calculator_Table[[#This Row],[Loading City]],ROUTES!G:G,CO2_Calculator_Table[[#This Row],[Unloading City]],ROUTES!C:C,CO2_Calculator_Table[[#This Row],[Route Detail]]) -> 1450 | S11: =SUMIFS(ROUTES!J:J,ROUTES!B:B,CO2_Calculator_Table[[#This Row],[Route]],ROUTES!E:E,CO2_Calculator_Table[[#This Row],[Loading City]],ROUTES!G:G,CO2_Calculator_Table[[#This Row],[Unloading City]],ROUTES!C:C,CO2_Calculator_Table[[#This Row],[Route Detail]]) -> 0 | T11: =SUMIFS(ROUTES!K:K,ROUTES!B:B,CO2_Calculator_Table[[#This Row],[Route]],ROUTES!E:E,CO2_Calculator_Table[[#This Row],[Loading City]],ROUTES!G:G,CO2_Calculator_Table[[#This Row],[Unloading City]],ROUTES!C:C,CO2_Calculator_Table[[#This Row],[Route Detail]]) -> 200 | U11: =SUMIFS(ROUTES!L:L,ROUTES!B:B,CO2_Calculator_Table[[#This Row],[Route]],ROUTES!E:E,CO2_Calculator_Table[[#This Row],[Loading City]],ROUTES!G:G,CO2_Calculator_Table[[#This Row],[Unloading City]],ROUTES!C:C,CO2_Calculator_Table[[#This Row],[Route Detail]]) -> 1175 | V11: =$V$6 -> 0.121 | W11: =$W$6 -> 0.012 | X11: =$X$6 -> 0.016 | Y11: =IF(CO2_Calculator_Table[[#This Row],[Pre-carriage ROAD (km, if electric)]]=0,(O11*P11*V11),(O11*Q11*V11)) -> 58.08 | Z11: =O11*R11*W11 -> 417.6 | AA11: =O11*S11*X11 -> 0 | AB11: =O11*T11*V11 -> 580.8 | AC11: =O11*U11*V11 -> 3412.2 | AD11: =Z11 -> 417.6 | AE11: =AA11 -> 0 | AF11: =Y11+AB11 -> 638.88 | AG11: =AD11+AE11+AF11 -> 1056.48 | AH11: =SUM(U11)*V11*O11 -> 3412.2 | AI11: =AH11-AG11 -> 2355.72
A12: 1 | C12: EXPORT | D12: SARP INTERMODAL | E12: TURKEY | F12: KOCAELİ | G12: IT | H12: 04011 | I12: PENDIK (TR) - BARI (IT)-TURKEY-KOCAELİ-IT-04011 | J12: PENDIK (TR) - BARI (IT) | K12: =VLOOKUP(CO2_Calculator_Table[[#This Row],[Referance Number (Carrier)]],#REF!,10,0) -> #REF! | L12: =VLOOKUP(CO2_Calculator_Table[[#This Row],[Referance Number (Carrier)]],#REF!,14,0) -> #REF! | M12: =VLOOKUP(CO2_Calculator_Table[[#This Row],[Referance Number (Carrier)]],#REF!,15,0) -> #REF! | N12: 24TON / 45HCPW BOX | O12: 24 | P12: =SUMIFS(ROUTES!H:H,ROUTES!B:B,CO2_Calculator_Table[[#This Row],[Route]],ROUTES!E:E,CO2_Calculator_Table[[#This Row],[Loading City]],ROUTES!G:G,CO2_Calculator_Table[[#This Row],[Unloading City]],ROUTES!C:C,CO2_Calculator_Table[[#This Row],[Route Detail]]) -> 20 | Q12: 0 | R12: =SUMIFS(ROUTES!I:I,ROUTES!B:B,CO2_Calculator_Table[[#This Row],[Route]],ROUTES!E:E,CO2_Calculator_Table[[#This Row],[Loading City]],ROUTES!G:G,CO2_Calculator_Table[[#This Row],[Unloading City]],ROUTES!C:C,CO2_Calculator_Table[[#This Row],[Route Detail]]) -> 1825 | S12: =SUMIFS(ROUTES!J:J,ROUTES!B:B,CO2_Calculator_Table[[#This Row],[Route]],ROUTES!E:E,CO2_Calculator_Table[[#This Row],[Loading City]],ROUTES!G:G,CO2_Calculator_Table[[#This Row],[Unloading City]],ROUTES!C:C,CO2_Calculator_Table[[#This Row],[Route Detail]]) -> 0 | T12: =SUMIFS(ROUTES!K:K,ROUTES!B:B,CO2_Calculator_Table[[#This Row],[Route]],ROUTES!E:E,CO2_Calculator_Table[[#This Row],[Loading City]],ROUTES!G:G,CO2_Calculator_Table[[#This Row],[Unloading City]],ROUTES!C:C,CO2_Calculator_Table[[#This Row],[Route Detail]]) -> 450 | U12: =SUMIFS(ROUTES!L:L,ROUTES!B:B,CO2_Calculator_Table[[#This Row],[Route]],ROUTES!E:E,CO2_Calculator_Table[[#This Row],[Loading City]],ROUTES!G:G,CO2_Calculator_Table[[#This Row],[Unloading City]],ROUTES!C:C,CO2_Calculator_Table[[#This Row],[Route Detail]]) -> 2370 | V12: =$V$6 -> 0.121 | W12: =$W$6 -> 0.012 | X12: =$X$6 -> 0.016 | Y12: =IF(CO2_Calculator_Table[[#This Row],[Pre-carriage ROAD (km, if electric)]]=0,(O12*P12*V12),(O12*Q12*V12)) -> 58.08 | Z12: =O12*R12*W12 -> 525.6 | AA12: =O12*S12*X12 -> 0 | AB12: =O12*T12*V12 -> 1306.8 | AC12: =O12*U12*V12 -> 6882.48 | AD12: =Z12 -> 525.6 | AE12: =AA12 -> 0 | AF12: =Y12+AB12 -> 1364.88 | AG12: =AD12+AE12+AF12 -> 1890.48 | AH12: =SUM(U12)*V12*O12 -> 6882.48 | AI12: =AH12-AG12 -> 4992
A13: 1 | C13: EXPORT | D13: SARP INTERMODAL | E13: TURKEY | F13: KOCAELİ | G13: ES | H13: 19171 | I13: YALOVA (TR) - SETE (FR)-TURKEY-KOCAELİ-ES-19171 | J13: YALOVA (TR) - SETE (FR) | K13: =VLOOKUP(CO2_Calculator_Table[[#This Row],[Referance Number (Carrier)]],#REF!,10,0) -> #REF! | L13: =VLOOKUP(CO2_Calculator_Table[[#This Row],[Referance Number (Carrier)]],#REF!,14,0) -> #REF! | M13: =VLOOKUP(CO2_Calculator_Table[[#This Row],[Referance Number (Carrier)]],#REF!,15,0) -> #REF! | N13: 24TON / 45HCPW BOX | O13: 24 | P13: =SUMIFS(ROUTES!H:H,ROUTES!B:B,CO2_Calculator_Table[[#This Row],[Route]],ROUTES!E:E,CO2_Calculator_Table[[#This Row],[Loading City]],ROUTES!G:G,CO2_Calculator_Table[[#This Row],[Unloading City]],ROUTES!C:C,CO2_Calculator_Table[[#This Row],[Route Detail]]) -> 45 | Q13: 0 | R13: =SUMIFS(ROUTES!I:I,ROUTES!B:B,CO2_Calculator_Table[[#This Row],[Route]],ROUTES!E:E,CO2_Calculator_Table[[#This Row],[Loading City]],ROUTES!G:G,CO2_Calculator_Table[[#This Row],[Unloading City]],ROUTES!C:C,CO2_Calculator_Table[[#This Row],[Route Detail]]) -> 3150 | S13: =SUMIFS(ROUTES!J:J,ROUTES!B:B,CO2_Calculator_Table[[#This Row],[Route]],ROUTES!E:E,CO2_Calculator_Table[[#This Row],[Loading City]],ROUTES!G:G,CO2_Calculator_Table[[#This Row],[Unloading City]],ROUTES!C:C,CO2_Calculator_Table[[#This Row],[Route Detail]]) -> 0 | T13: =SUMIFS(ROUTES!K:K,ROUTES!B:B,CO2_Calculator_Table[[#This Row],[Route]],ROUTES!E:E,CO2_Calculator_Table[[#This Row],[Loading City]],ROUTES!G:G,CO2_Calculator_Table[[#This Row],[Unloading City]],ROUTES!C:C,CO2_Calculator_Table[[#This Row],[Route Detail]]) -> 880 | U13: =SUMIFS(ROUTES!L:L,ROUTES!B:B,CO2_Calculator_Table[[#This Row],[Route]],ROUTES!E:E,CO2_Calculator_Table[[#This Row],[Loading City]],ROUTES!G:G,CO2_Calculator_Table[[#This Row],[Unloading City]],ROUTES!C:C,CO2_Calculator_Table[[#This Row],[Route Detail]]) -> 3590 | V13: =$V$6 -> 0.121 | W13: =$W$6 -> 0.012 | X13: =$X$6 -> 0.016 | Y13: =IF(CO2_Calculator_Table[[#This Row],[Pre-carriage ROAD (km, if electric)]]=0,(O13*P13*V13),(O13*Q13*V13)) -> 130.68 | Z13: =O13*R13*W13 -> 907.2 | AA13: =O13*S13*X13 -> 0 | AB13: =O13*T13*V13 -> 2555.52 | AC13: =O13*U13*V13 -> 10425.36 | AD13: =Z13 -> 907.2 | AE13: =AA13 -> 0 | AF13: =Y13+AB13 -> 2686.2 | AG13: =AD13+AE13+AF13 -> 3593.4 | AH13: =SUM(U13)*V13*O13 -> 10425.36 | AI13: =AH13-AG13 -> 6831.96
A14: 1 | C14: EXPORT | D14: SARP INTERMODAL | E14: TURKEY | F14: KOCAELİ | G14: GB | H14: S80 3FY | I14: PENDIK (TR) - TRIESTE (IT) - DUISBURG (DE)-TURKEY-KOCAELİ-GB-S80 3FY | J14: PENDIK (TR) - TRIESTE (IT) - DUISBURG (DE) | K14: =VLOOKUP(CO2_Calculator_Table[[#This Row],[Referance Number (Carrier)]],#REF!,10,0) -> #REF! | L14: =VLOOKUP(CO2_Calculator_Table[[#This Row],[Referance Number (Carrier)]],#REF!,14,0) -> #REF! | M14: =VLOOKUP(CO2_Calculator_Table[[#This Row],[Referance Number (Carrier)]],#REF!,15,0) -> #REF! | N14: 24TON / 45HCPW BOX | O14: 24 | P14: =SUMIFS(ROUTES!H:H,ROUTES!B:B,CO2_Calculator_Table[[#This Row],[Route]],ROUTES!E:E,CO2_Calculator_Table[[#This Row],[Loading City]],ROUTES!G:G,CO2_Calculator_Table[[#This Row],[Unloading City]],ROUTES!C:C,CO2_Calculator_Table[[#This Row],[Route Detail]]) -> 20 | Q14: 0 | R14: =SUMIFS(ROUTES!I:I,ROUTES!B:B,CO2_Calculator_Table[[#This Row],[Route]],ROUTES!E:E,CO2_Calculator_Table[[#This Row],[Loading City]],ROUTES!G:G,CO2_Calculator_Table[[#This Row],[Unloading City]],ROUTES!C:C,CO2_Calculator_Table[[#This Row],[Route Detail]]) -> 2720 | S14: =SUMIFS(ROUTES!J:J,ROUTES!B:B,CO2_Calculator_Table[[#This Row],[Route]],ROUTES!E:E,CO2_Calculator_Table[[#This Row],[Loading City]],ROUTES!G:G,CO2_Calculator_Table[[#This Row],[Unloading City]],ROUTES!C:C,CO2_Calculator_Table[[#This Row],[Route Detail]]) -> 1190 | T14: =SUMIFS(ROUTES!K:K,ROUTES!B:B,CO2_Calculator_Table[[#This Row],[Route]],ROUTES!E:E,CO2_Calculator_Table[[#This Row],[Loading City]],ROUTES!G:G,CO2_Calculator_Table[[#This Row],[Unloading City]],ROUTES!C:C,CO2_Calculator_Table[[#This Row],[Route Detail]]) -> 540 | U14: =SUMIFS(ROUTES!L:L,ROUTES!B:B,CO2_Calculator_Table[[#This Row],[Route]],ROUTES!E:E,CO2_Calculator_Table[[#This Row],[Loading City]],ROUTES!G:G,CO2_Calculator_Table[[#This Row],[Unloading City]],ROUTES!C:C,CO2_Calculator_Table[[#This Row],[Route Detail]]) -> 3350 | V14: =$V$6 -> 0.121 | W14: =$W$6 -> 0.012 | X14: =$X$6 -> 0.016 | Y14: =IF(CO2_Calculator_Table[[#This Row],[Pre-carriage ROAD (km, if electric)]]=0,(O14*P14*V14),(O14*Q14*V14)) -> 58.08 | Z14: =O14*R14*W14 -> 783.36 | AA14: =O14*S14*X14 -> 456.96 | AB14: =O14*T14*V14 -> 1568.16 | AC14: =O14*U14*V14 -> 9728.4 | AD14: =Z14 -> 783.36 | AE14: =AA14 -> 456.96 | AF14: =Y14+AB14 -> 1626.24 | AG14: =AD14+AE14+AF14 -> 2866.56 | AH14: =SUM(U14)*V14*O14 -> 9728.4 | AI14: =AH14-AG14 -> 6861.84
A15: 1 | C15: EXPORT | D15: SARP INTERMODAL | E15: TURKEY | F15: KOCAELİ | G15: NL | H15: 4004 | I15: PENDIK (TR) - TRIESTE (IT) - DUISBURG (DE)-TURKEY-KOCAELİ-NL-4004 | J15: PENDIK (TR) - TRIESTE (IT) - DUISBURG (DE) | K15: =VLOOKUP(CO2_Calculator_Table[[#This Row],[Referance Number (Carrier)]],#REF!,10,0) -> #REF! | L15: =VLOOKUP(CO2_Calculator_Table[[#This Row],[Referance Number (Carrier)]],#REF!,14,0) -> #REF! | M15: =VLOOKUP(CO2_Calculator_Table[[#This Row],[Referance Number (Carrier)]],#REF!,15,0) -> #REF! | N15: 24TON / 45HCPW BOX | O15: 24 | P15: =SUMIFS(ROUTES!H:H,ROUTES!B:B,CO2_Calculator_Table[[#This Row],[Route]],ROUTES!E:E,CO2_Calculator_Table[[#This Row],[Loading City]],ROUTES!G:G,CO2_Calculator_Table[[#This Row],[Unloading City]],ROUTES!C:C,CO2_Calculator_Table[[#This Row],[Route Detail]]) -> 20 | Q15: 0 | R15: =SUMIFS(ROUTES!I:I,ROUTES!B:B,CO2_Calculator_Table[[#This Row],[Route]],ROUTES!E:E,CO2_Calculator_Table[[#This Row],[Loading City]],ROUTES!G:G,CO2_Calculator_Table[[#This Row],[Unloading City]],ROUTES!C:C,CO2_Calculator_Table[[#This Row],[Route Detail]]) -> 2500 | S15: =SUMIFS(ROUTES!J:J,ROUTES!B:B,CO2_Calculator_Table[[#This Row],[Route]],ROUTES!E:E,CO2_Calculator_Table[[#This Row],[Loading City]],ROUTES!G:G,CO2_Calculator_Table[[#This Row],[Unloading City]],ROUTES!C:C,CO2_Calculator_Table[[#This Row],[Route Detail]]) -> 1190 | T15: =SUMIFS(ROUTES!K:K,ROUTES!B:B,CO2_Calculator_Table[[#This Row],[Route]],ROUTES!E:E,CO2_Calculator_Table[[#This Row],[Loading City]],ROUTES!G:G,CO2_Calculator_Table[[#This Row],[Unloading City]],ROUTES!C:C,CO2_Calculator_Table[[#This Row],[Route Detail]]) -> 130 | U15: =SUMIFS(ROUTES!L:L,ROUTES!B:B,CO2_Calculator_Table[[#This Row],[Route]],ROUTES!E:E,CO2_Calculator_Table[[#This Row],[Loading City]],ROUTES!G:G,CO2_Calculator_Table[[#This Row],[Unloading City]],ROUTES!C:C,CO2_Calculator_Table[[#This Row],[Route Detail]]) -> 2730 | V15: =$V$6 -> 0.121 | W15: =$W$6 -> 0.012 | X15: =$X$6 -> 0.016 | Y15: =IF(CO2_Calculator_Table[[#This Row],[Pre-carriage ROAD (km, if electric)]]=0,(O15*P15*V15),(O15*Q15*V15)) -> 58.08 | Z15: =O15*R15*W15 -> 720 | AA15: =O15*S15*X15 -> 456.96 | AB15: =O15*T15*V15 -> 377.52 | AC15: =O15*U15*V15 -> 7927.92 | AD15: =Z15 -> 720 | AE15: =AA15 -> 456.96 | AF15: =Y15+AB15 -> 435.6 | AG15: =AD15+AE15+AF15 -> 1612.56 | AH15: =SUM(U15)*V15*O15 -> 7927.92 | AI15: =AH15-AG15 -> 6315.36
A16: 1 | C16: EXPORT | D16: SARP INTERMODAL | E16: TURKEY | F16: KOCAELİ | G16: FR | H16: 60802 | I16: YALOVA (TR) - SETE (FR)-TURKEY-KOCAELİ-FR-60802 | J16: YALOVA (TR) - SETE (FR) | K16: =VLOOKUP(CO2_Calculator_Table[[#This Row],[Referance Number (Carrier)]],#REF!,10,0) -> #REF! | L16: =VLOOKUP(CO2_Calculator_Table[[#This Row],[Referance Number (Carrier)]],#REF!,14,0) -> #REF! | M16: =VLOOKUP(CO2_Calculator_Table[[#This Row],[Referance Number (Carrier)]],#REF!,15,0) -> #REF! | N16: 24TON / 45HCPW BOX | O16: 24 | P16: =SUMIFS(ROUTES!H:H,ROUTES!B:B,CO2_Calculator_Table[[#This Row],[Route]],ROUTES!E:E,CO2_Calculator_Table[[#This Row],[Loading City]],ROUTES!G:G,CO2_Calculator_Table[[#This Row],[Unloading City]],ROUTES!C:C,CO2_Calculator_Table[[#This Row],[Route Detail]]) -> 45 | Q16: 0 | R16: =SUMIFS(ROUTES!I:I,ROUTES!B:B,CO2_Calculator_Table[[#This Row],[Route]],ROUTES!E:E,CO2_Calculator_Table[[#This Row],[Loading City]],ROUTES!G:G,CO2_Calculator_Table[[#This Row],[Unloading City]],ROUTES!C:C,CO2_Calculator_Table[[#This Row],[Route Detail]]) -> 3150 | S16: =SUMIFS(ROUTES!J:J,ROUTES!B:B,CO2_Calculator_Table[[#This Row],[Route]],ROUTES!E:E,CO2_Calculator_Table[[#This Row],[Loading City]],ROUTES!G:G,CO2_Calculator_Table[[#This Row],[Unloading City]],ROUTES!C:C,CO2_Calculator_Table[[#This Row],[Route Detail]]) -> 0 | T16: =SUMIFS(ROUTES!K:K,ROUTES!B:B,CO2_Calculator_Table[[#This Row],[Route]],ROUTES!E:E,CO2_Calculator_Table[[#This Row],[Loading City]],ROUTES!G:G,CO2_Calculator_Table[[#This Row],[Unloading City]],ROUTES!C:C,CO2_Calculator_Table[[#This Row],[Route Detail]]) -> 895 | U16: =SUMIFS(ROUTES!L:L,ROUTES!B:B,CO2_Calculator_Table[[#This Row],[Route]],ROUTES!E:E,CO2_Calculator_Table[[#This Row],[Loading City]],ROUTES!G:G,CO2_Calculator_Table[[#This Row],[Unloading City]],ROUTES!C:C,CO2_Calculator_Table[[#This Row],[Route Detail]]) -> 2800 | V16: =$V$6 -> 0.121 | W16: =$W$6 -> 0.012 | X16: =$X$6 -> 0.016 | Y16: =IF(CO2_Calculator_Table[[#This Row],[Pre-carriage ROAD (km, if electric)]]=0,(O16*P16*V16),(O16*Q16*V16)) -> 130.68 | Z16: =O16*R16*W16 -> 907.2 | AA16: =O16*S16*X16 -> 0 | AB16: =O16*T16*V16 -> 2599.08 | AC16: =O16*U16*V16 -> 8131.2 | AD16: =Z16 -> 907.2 | AE16: =AA16 -> 0 | AF16: =Y16+AB16 -> 2729.76 | AG16: =AD16+AE16+AF16 -> 3636.96 | AH16: =SUM(U16)*V16*O16 -> 8131.2 | AI16: =AH16-AG16 -> 4494.24
A17: 1 | C17: EXPORT | D17: SARP INTERMODAL | E17: TURKEY | F17: KOCAELİ | G17: HR | H17: 1000 | I17: PENDIK (TR) - TRIESTE (IT)-TURKEY-KOCAELİ-HR-1000 | J17: PENDIK (TR) - TRIESTE (IT) | K17: =VLOOKUP(CO2_Calculator_Table[[#This Row],[Referance Number (Carrier)]],#REF!,10,0) -> #REF! | L17: =VLOOKUP(CO2_Calculator_Table[[#This Row],[Referance Number (Carrier)]],#REF!,14,0) -> #REF! | M17: =VLOOKUP(CO2_Calculator_Table[[#This Row],[Referance Number (Carrier)]],#REF!,15,0) -> #REF! | N17: 24TON / 45HCPW BOX | O17: 24 | P17: =SUMIFS(ROUTES!H:H,ROUTES!B:B,CO2_Calculator_Table[[#This Row],[Route]],ROUTES!E:E,CO2_Calculator_Table[[#This Row],[Loading City]],ROUTES!G:G,CO2_Calculator_Table[[#This Row],[Unloading City]],ROUTES!C:C,CO2_Calculator_Table[[#This Row],[Route Detail]]) -> 20 | Q17: 0 | R17: =SUMIFS(ROUTES!I:I,ROUTES!B:B,CO2_Calculator_Table[[#This Row],[Route]],ROUTES!E:E,CO2_Calculator_Table[[#This Row],[Loading City]],ROUTES!G:G,CO2_Calculator_Table[[#This Row],[Unloading City]],ROUTES!C:C,CO2_Calculator_Table[[#This Row],[Route Detail]]) -> 2500 | S17: =SUMIFS(ROUTES!J:J,ROUTES!B:B,CO2_Calculator_Table[[#This Row],[Route]],ROUTES!E:E,CO2_Calculator_Table[[#This Row],[Loading City]],ROUTES!G:G,CO2_Calculator_Table[[#This Row],[Unloading City]],ROUTES!C:C,CO2_Calculator_Table[[#This Row],[Route Detail]]) -> 0 | T17: =SUMIFS(ROUTES!K:K,ROUTES!B:B,CO2_Calculator_Table[[#This Row],[Route]],ROUTES!E:E,CO2_Calculator_Table[[#This Row],[Loading City]],ROUTES!G:G,CO2_Calculator_Table[[#This Row],[Unloading City]],ROUTES!C:C,CO2_Calculator_Table[[#This Row],[Route Detail]]) -> 235 | U17: =SUMIFS(ROUTES!L:L,ROUTES!B:B,CO2_Calculator_Table[[#This Row],[Route]],ROUTES!E:E,CO2_Calculator_Table[[#This Row],[Loading City]],ROUTES!G:G,CO2_Calculator_Table[[#This Row],[Unloading City]],ROUTES!C:C,CO2_Calculator_Table[[#This Row],[Route Detail]]) -> 1420 | V17: =$V$6 -> 0.121 | W17: =$W$6 -> 0.012 | X17: =$X$6 -> 0.016 | Y17: =IF(CO2_Calculator_Table[[#This Row],[Pre-carriage ROAD (km, if electric)]]=0,(O17*P17*V17),(O17*Q17*V17)) -> 58.08 | Z17: =O17*R17*W17 -> 720 | AA17: =O17*S17*X17 -> 0 | AB17: =O17*T17*V17 -> 682.44 | AC17: =O17*U17*V17 -> 4123.68 | AD17: =Z17 -> 720 | AE17: =AA17 -> 0 | AF17: =Y17+AB17 -> 740.52 | AG17: =AD17+AE17+AF17 -> 1460.52 | AH17: =SUM(U17)*V17*O17 -> 4123.68 | AI17: =AH17-AG17 -> 2663.16
A18: 1 | C18: EXPORT | D18: SARP INTERMODAL | E18: TURKEY | F18: KOCAELİ | G18: SI | H18: 1000 | I18: PENDIK (TR) - TRIESTE (IT)-TURKEY-KOCAELİ-SI-1000 | J18: PENDIK (TR) - TRIESTE (IT) | K18: =VLOOKUP(CO2_Calculator_Table[[#This Row],[Referance Number (Carrier)]],#REF!,10,0) -> #REF! | L18: =VLOOKUP(CO2_Calculator_Table[[#This Row],[Referance Number (Carrier)]],#REF!,14,0) -> #REF! | M18: =VLOOKUP(CO2_Calculator_Table[[#This Row],[Referance Number (Carrier)]],#REF!,15,0) -> #REF! | N18: 24TON / 45HCPW BOX | O18: 24 | P18: =SUMIFS(ROUTES!H:H,ROUTES!B:B,CO2_Calculator_Table[[#This Row],[Route]],ROUTES!E:E,CO2_Calculator_Table[[#This Row],[Loading City]],ROUTES!G:G,CO2_Calculator_Table[[#This Row],[Unloading City]],ROUTES!C:C,CO2_Calculator_Table[[#This Row],[Route Detail]]) -> 20 | Q18: 0 | R18: =SUMIFS(ROUTES!I:I,ROUTES!B:B,CO2_Calculator_Table[[#This Row],[Route]],ROUTES!E:E,CO2_Calculator_Table[[#This Row],[Loading City]],ROUTES!G:G,CO2_Calculator_Table[[#This Row],[Unloading City]],ROUTES!C:C,CO2_Calculator_Table[[#This Row],[Route Detail]]) -> 2500 | S18: =SUMIFS(ROUTES!J:J,ROUTES!B:B,CO2_Calculator_Table[[#This Row],[Route]],ROUTES!E:E,CO2_Calculator_Table[[#This Row],[Loading City]],ROUTES!G:G,CO2_Calculator_Table[[#This Row],[Unloading City]],ROUTES!C:C,CO2_Calculator_Table[[#This Row],[Route Detail]]) -> 0 | T18: =SUMIFS(ROUTES!K:K,ROUTES!B:B,CO2_Calculator_Table[[#This Row],[Route]],ROUTES!E:E,CO2_Calculator_Table[[#This Row],[Loading City]],ROUTES!G:G,CO2_Calculator_Table[[#This Row],[Unloading City]],ROUTES!C:C,CO2_Calculator_Table[[#This Row],[Route Detail]]) -> 100 | U18: =SUMIFS(ROUTES!L:L,ROUTES!B:B,CO2_Calculator_Table[[#This Row],[Route]],ROUTES!E:E,CO2_Calculator_Table[[#This Row],[Loading City]],ROUTES!G:G,CO2_Calculator_Table[[#This Row],[Unloading City]],ROUTES!C:C,CO2_Calculator_Table[[#This Row],[Route Detail]]) -> 1560 | V18: =$V$6 -> 0.121 | W18: =$W$6 -> 0.012 | X18: =$X$6 -> 0.016 | Y18: =IF(CO2_Calculator_Table[[#This Row],[Pre-carriage ROAD (km, if electric)]]=0,(O18*P18*V18),(O18*Q18*V18)) -> 58.08 | Z18: =O18*R18*W18 -> 720 | AA18: =O18*S18*X18 -> 0 | AB18: =O18*T18*V18 -> 290.4 | AC18: =O18*U18*V18 -> 4530.24 | AD18: =Z18 -> 720 | AE18: =AA18 -> 0 | AF18: =Y18+AB18 -> 348.48 | AG18: =AD18+AE18+AF18 -> 1068.48 | AH18: =SUM(U18)*V18*O18 -> 4530.24 | AI18: =AH18-AG18 -> 3461.76
A19: 1 | C19: EXPORT | D19: SARP INTERMODAL | E19: TURKEY | F19: KOCAELİ | G19: BE | H19: 9130 | I19: PENDIK (TR) - TRIESTE (IT) - DUISBURG (DE)-TURKEY-KOCAELİ-BE-9130 | J19: PENDIK (TR) - TRIESTE (IT) - DUISBURG (DE) | K19: =VLOOKUP(CO2_Calculator_Table[[#This Row],[Referance Number (Carrier)]],#REF!,10,0) -> #REF! | L19: =VLOOKUP(CO2_Calculator_Table[[#This Row],[Referance Number (Carrier)]],#REF!,14,0) -> #REF! | M19: =VLOOKUP(CO2_Calculator_Table[[#This Row],[Referance Number (Carrier)]],#REF!,15,0) -> #REF! | N19: 24TON / 45HCPW BOX | O19: 24 | P19: =SUMIFS(ROUTES!H:H,ROUTES!B:B,CO2_Calculator_Table[[#This Row],[Route]],ROUTES!E:E,CO2_Calculator_Table[[#This Row],[Loading City]],ROUTES!G:G,CO2_Calculator_Table[[#This Row],[Unloading City]],ROUTES!C:C,CO2_Calculator_Table[[#This Row],[Route Detail]]) -> 20 | Q19: 0 | R19: =SUMIFS(ROUTES!I:I,ROUTES!B:B,CO2_Calculator_Table[[#This Row],[Route]],ROUTES!E:E,CO2_Calculator_Table[[#This Row],[Loading City]],ROUTES!G:G,CO2_Calculator_Table[[#This Row],[Unloading City]],ROUTES!C:C,CO2_Calculator_Table[[#This Row],[Route Detail]]) -> 2500 | S19: =SUMIFS(ROUTES!J:J,ROUTES!B:B,CO2_Calculator_Table[[#This Row],[Route]],ROUTES!E:E,CO2_Calculator_Table[[#This Row],[Loading City]],ROUTES!G:G,CO2_Calculator_Table[[#This Row],[Unloading City]],ROUTES!C:C,CO2_Calculator_Table[[#This Row],[Route Detail]]) -> 1190 | T19: =SUMIFS(ROUTES!K:K,ROUTES!B:B,CO2_Calculator_Table[[#This Row],[Route]],ROUTES!E:E,CO2_Calculator_Table[[#This Row],[Loading City]],ROUTES!G:G,CO2_Calculator_Table[[#This Row],[Unloading City]],ROUTES!C:C,CO2_Calculator_Table[[#This Row],[Route Detail]]) -> 200 | U19: =SUMIFS(ROUTES!L:L,ROUTES!B:B,CO2_Calculator_Table[[#This Row],[Route]],ROUTES!E:E,CO2_Calculator_Table[[#This Row],[Loading City]],ROUTES!G:G,CO2_Calculator_Table[[#This Row],[Unloading City]],ROUTES!C:C,CO2_Calculator_Table[[#This Row],[Route Detail]]) -> 2760 | V19: =$V$6 -> 0.121 | W19: =$W$6 -> 0.012 | X19: =$X$6 -> 0.016 | Y19: =IF(CO2_Calculator_Table[[#This Row],[Pre-carriage ROAD (km, if electric)]]=0,(O19*P19*V19),(O19*Q19*V19)) -> 58.08 | Z19: =O19*R19*W19 -> 720 | AA19: =O19*S19*X19 -> 456.96 | AB19: =O19*T19*V19 -> 580.8 | AC19: =O19*U19*V19 -> 8015.04 | AD19: =Z19 -> 720 | AE19: =AA19 -> 456.96 | AF19: =Y19+AB19 -> 638.88 | AG19: =AD19+AE19+AF19 -> 1815.84 | AH19: =SUM(U19)*V19*O19 -> 8015.04 | AI19: =AH19-AG19 -> 6199.2
A20: 1 | C20: EXPORT | D20: SARP INTERMODAL | E20: GREECE | F20: PİREAS | G20: TR | H20: 41400 | I20: PATRAS (GR) - PENDIK (TR)-GREECE-PİREAS-TR-41400 | J20: PATRAS (GR) - PENDIK (TR) | K20: =VLOOKUP(CO2_Calculator_Table[[#This Row],[Referance Number (Carrier)]],#REF!,10,0) -> #REF! | L20: =VLOOKUP(CO2_Calculator_Table[[#This Row],[Referance Number (Carrier)]],#REF!,14,0) -> #REF! | M20: =VLOOKUP(CO2_Calculator_Table[[#This Row],[Referance Number (Carrier)]],#REF!,15,0) -> #REF! | N20: 24TON / 45HCPW BOX | O20: 24 | P20: =SUMIFS(ROUTES!H:H,ROUTES!B:B,CO2_Calculator_Table[[#This Row],[Route]],ROUTES!E:E,CO2_Calculator_Table[[#This Row],[Loading City]],ROUTES!G:G,CO2_Calculator_Table[[#This Row],[Unloading City]],ROUTES!C:C,CO2_Calculator_Table[[#This Row],[Route Detail]]) -> 220 | Q20: 0 | R20: =SUMIFS(ROUTES!I:I,ROUTES!B:B,CO2_Calculator_Table[[#This Row],[Route]],ROUTES!E:E,CO2_Calculator_Table[[#This Row],[Loading City]],ROUTES!G:G,CO2_Calculator_Table[[#This Row],[Unloading City]],ROUTES!C:C,CO2_Calculator_Table[[#This Row],[Route Detail]]) -> 1450 | S20: =SUMIFS(ROUTES!J:J,ROUTES!B:B,CO2_Calculator_Table[[#This Row],[Route]],ROUTES!E:E,CO2_Calculator_Table[[#This Row],[Loading City]],ROUTES!G:G,CO2_Calculator_Table[[#This Row],[Unloading City]],ROUTES!C:C,CO2_Calculator_Table[[#This Row],[Route Detail]]) -> 0 | T20: =SUMIFS(ROUTES!K:K,ROUTES!B:B,CO2_Calculator_Table[[#This Row],[Route]],ROUTES!E:E,CO2_Calculator_Table[[#This Row],[Loading City]],ROUTES!G:G,CO2_Calculator_Table[[#This Row],[Unloading City]],ROUTES!C:C,CO2_Calculator_Table[[#This Row],[Route Detail]]) -> 20 | U20: =SUMIFS(ROUTES!L:L,ROUTES!B:B,CO2_Calculator_Table[[#This Row],[Route]],ROUTES!E:E,CO2_Calculator_Table[[#This Row],[Loading City]],ROUTES!G:G,CO2_Calculator_Table[[#This Row],[Unloading City]],ROUTES!C:C,CO2_Calculator_Table[[#This Row],[Route Detail]]) -> 1175 | V20: =$V$6 -> 0.121 | W20: =$W$6 -> 0.012 | X20: =$X$6 -> 0.016 | Y20: =IF(CO2_Calculator_Table[[#This Row],[Pre-carriage ROAD (km, if electric)]]=0,(O20*P20*V20),(O20*Q20*V20)) -> 638.88 | Z20: =O20*R20*W20 -> 417.6 | AA20: =O20*S20*X20 -> 0 | AB20: =O20*T20*V20 -> 58.08 | AC20: =O20*U20*V20 -> 3412.2 | AD20: =Z20 -> 417.6 | AE20: =AA20 -> 0 | AF20: =Y20+AB20 -> 696.96 | AG20: =AD20+AE20+AF20 -> 1114.56 | AH20: =SUM(U20)*V20*O20 -> 3412.2 | AI20: =AH20-AG20 -> 2297.64
A21: 1 | C21: EXPORT | D21: SARP INTERMODAL | E21: ITALY | F21: ANZIO | G21: TR | H21: 41400 | I21: BARI (IT) - PENDIK (TR)-ITALY-ANZIO-TR-41400 | J21: BARI (IT) - PENDIK (TR) | K21: =VLOOKUP(CO2_Calculator_Table[[#This Row],[Referance Number (Carrier)]],#REF!,10,0) -> #REF! | L21: =VLOOKUP(CO2_Calculator_Table[[#This Row],[Referance Number (Carrier)]],#REF!,14,0) -> #REF! | M21: =VLOOKUP(CO2_Calculator_Table[[#This Row],[Referance Number (Carrier)]],#REF!,15,0) -> #REF! | N21: 24TON / 45HCPW BOX | O21: 24 | P21: =SUMIFS(ROUTES!H:H,ROUTES!B:B,CO2_Calculator_Table[[#This Row],[Route]],ROUTES!E:E,CO2_Calculator_Table[[#This Row],[Loading City]],ROUTES!G:G,CO2_Calculator_Table[[#This Row],[Unloading City]],ROUTES!C:C,CO2_Calculator_Table[[#This Row],[Route Detail]]) -> 450 | Q21: 0 | R21: =SUMIFS(ROUTES!I:I,ROUTES!B:B,CO2_Calculator_Table[[#This Row],[Route]],ROUTES!E:E,CO2_Calculator_Table[[#This Row],[Loading City]],ROUTES!G:G,CO2_Calculator_Table[[#This Row],[Unloading City]],ROUTES!C:C,CO2_Calculator_Table[[#This Row],[Route Detail]]) -> 1825 | S21: =SUMIFS(ROUTES!J:J,ROUTES!B:B,CO2_Calculator_Table[[#This Row],[Route]],ROUTES!E:E,CO2_Calculator_Table[[#This Row],[Loading City]],ROUTES!G:G,CO2_Calculator_Table[[#This Row],[Unloading City]],ROUTES!C:C,CO2_Calculator_Table[[#This Row],[Route Detail]]) -> 0 | T21: =SUMIFS(ROUTES!K:K,ROUTES!B:B,CO2_Calculator_Table[[#This Row],[Route]],ROUTES!E:E,CO2_Calculator_Table[[#This Row],[Loading City]],ROUTES!G:G,CO2_Calculator_Table[[#This Row],[Unloading City]],ROUTES!C:C,CO2_Calculator_Table[[#This Row],[Route Detail]]) -> 20 | U21: =SUMIFS(ROUTES!L:L,ROUTES!B:B,CO2_Calculator_Table[[#This Row],[Route]],ROUTES!E:E,CO2_Calculator_Table[[#This Row],[Loading City]],ROUTES!G:G,CO2_Calculator_Table[[#This Row],[Unloading City]],ROUTES!C:C,CO2_Calculator_Table[[#This Row],[Route Detail]]) -> 2375 | V21: =$V$6 -> 0.121 | W21: =$W$6 -> 0.012 | X21: =$X$6 -> 0.016 | Y21: =IF(CO2_Calculator_Table[[#This Row],[Pre-carriage ROAD (km, if electric)]]=0,(O21*P21*V21),(O21*Q21*V21)) -> 1306.8 | Z21: =O21*R21*W21 -> 525.6 | AA21: =O21*S21*X21 -> 0 | AB21: =O21*T21*V21 -> 58.08 | AC21: =O21*U21*V21 -> 6897 | AD21: =Z21 -> 525.6 | AE21: =AA21 -> 0 | AF21: =Y21+AB21 -> 1364.88 | AG21: =AD21+AE21+AF21 -> 1890.48 | AH21: =SUM(U21)*V21*O21 -> 6897 | AI21: =AH21-AG21 -> 5006.52
A22: 1 | C22: EXPORT | D22: SARP INTERMODAL | E22: ITALY | F22: ANZIO | G22: GR | H22: 19300 | I22: TRA - TRIESTE (IT) - PATRAS (GR)-ITALY-ANZIO-GR-19300 | J22: TRA - TRIESTE (IT) - PATRAS (GR) | K22: =VLOOKUP(CO2_Calculator_Table[[#This Row],[Referance Number (Carrier)]],#REF!,10,0) -> #REF! | L22: =VLOOKUP(CO2_Calculator_Table[[#This Row],[Referance Number (Carrier)]],#REF!,14,0) -> #REF! | M22: =VLOOKUP(CO2_Calculator_Table[[#This Row],[Referance Number (Carrier)]],#REF!,15,0) -> #REF! | N22: 24TON / 45HCPW BOX | O22: 24 | P22: =SUMIFS(ROUTES!H:H,ROUTES!B:B,CO2_Calculator_Table[[#This Row],[Route]],ROUTES!E:E,CO2_Calculator_Table[[#This Row],[Loading City]],ROUTES!G:G,CO2_Calculator_Table[[#This Row],[Unloading City]],ROUTES!C:C,CO2_Calculator_Table[[#This Row],[Route Detail]]) -> 745 | Q22: 0 | R22: =SUMIFS(ROUTES!I:I,ROUTES!B:B,CO2_Calculator_Table[[#This Row],[Route]],ROUTES!E:E,CO2_Calculator_Table[[#This Row],[Loading City]],ROUTES!G:G,CO2_Calculator_Table[[#This Row],[Unloading City]],ROUTES!C:C,CO2_Calculator_Table[[#This Row],[Route Detail]]) -> 1225 | S22: =SUMIFS(ROUTES!J:J,ROUTES!B:B,CO2_Calculator_Table[[#This Row],[Route]],ROUTES!E:E,CO2_Calculator_Table[[#This Row],[Loading City]],ROUTES!G:G,CO2_Calculator_Table[[#This Row],[Unloading City]],ROUTES!C:C,CO2_Calculator_Table[[#This Row],[Route Detail]]) -> 0 | T22: =SUMIFS(ROUTES!K:K,ROUTES!B:B,CO2_Calculator_Table[[#This Row],[Route]],ROUTES!E:E,CO2_Calculator_Table[[#This Row],[Loading City]],ROUTES!G:G,CO2_Calculator_Table[[#This Row],[Unloading City]],ROUTES!C:C,CO2_Calculator_Table[[#This Row],[Route Detail]]) -> 200 | U22: =SUMIFS(ROUTES!L:L,ROUTES!B:B,CO2_Calculator_Table[[#This Row],[Route]],ROUTES!E:E,CO2_Calculator_Table[[#This Row],[Loading City]],ROUTES!G:G,CO2_Calculator_Table[[#This Row],[Unloading City]],ROUTES!C:C,CO2_Calculator_Table[[#This Row],[Route Detail]]) -> 2450 | V22: =$V$6 -> 0.121 | W22: =$W$6 -> 0.012 | X22: =$X$6 -> 0.016 | Y22: =IF(CO2_Calculator_Table[[#This Row],[Pre-carriage ROAD (km, if electric)]]=0,(O22*P22*V22),(O22*Q22*V22)) -> 2163.48 | Z22: =O22*R22*W22 -> 352.8 | AA22: =O22*S22*X22 -> 0 | AB22: =O22*T22*V22 -> 580.8 | AC22: =O22*U22*V22 -> 7114.8 | AD22: =Z22 -> 352.8 | AE22: =AA22 -> 0 | AF22: =Y22+AB22 -> 2744.28 | AG22: =AD22+AE22+AF22 -> 3097.08 | AH22: =SUM(U22)*V22*O22 -> 7114.8 | AI22: =AH22-AG22 -> 4017.72
E23: TURKEY | F23: GEBZE | G23: DK | H23: 4450 | I23: PENDIK (TR) - TRIESTE (IT)-TURKEY-GEBZE-DK-4450 | J23: PENDIK (TR) - TRIESTE (IT) | N23: 24TON / 45HCPW BOX | O23: 24 | P23: =SUMIFS(ROUTES!H:H,ROUTES!B:B,CO2_Calculator_Table[[#This Row],[Route]],ROUTES!E:E,CO2_Calculator_Table[[#This Row],[Loading City]],ROUTES!G:G,CO2_Calculator_Table[[#This Row],[Unloading City]],ROUTES!C:C,CO2_Calculator_Table[[#This Row],[Route Detail]]) -> 20 | Q23: 0 | R23: =SUMIFS(ROUTES!I:I,ROUTES!B:B,CO2_Calculator_Table[[#This Row],[Route]],ROUTES!E:E,CO2_Calculator_Table[[#This Row],[Loading City]],ROUTES!G:G,CO2_Calculator_Table[[#This Row],[Unloading City]],ROUTES!C:C,CO2_Calculator_Table[[#This Row],[Route Detail]]) -> 2500 | S23: =SUMIFS(ROUTES!J:J,ROUTES!B:B,CO2_Calculator_Table[[#This Row],[Route]],ROUTES!E:E,CO2_Calculator_Table[[#This Row],[Loading City]],ROUTES!G:G,CO2_Calculator_Table[[#This Row],[Unloading City]],ROUTES!C:C,CO2_Calculator_Table[[#This Row],[Route Detail]]) -> 0 | T23: =SUMIFS(ROUTES!K:K,ROUTES!B:B,CO2_Calculator_Table[[#This Row],[Route]],ROUTES!E:E,CO2_Calculator_Table[[#This Row],[Loading City]],ROUTES!G:G,CO2_Calculator_Table[[#This Row],[Unloading City]],ROUTES!C:C,CO2_Calculator_Table[[#This Row],[Route Detail]]) -> 1690 | U23: =SUMIFS(ROUTES!L:L,ROUTES!B:B,CO2_Calculator_Table[[#This Row],[Route]],ROUTES!E:E,CO2_Calculator_Table[[#This Row],[Loading City]],ROUTES!G:G,CO2_Calculator_Table[[#This Row],[Unloading City]],ROUTES!C:C,CO2_Calculator_Table[[#This Row],[Route Detail]]) -> 2725 | V23: =$V$6 -> 0.121 | W23: =$W$6 -> 0.012 | X23: =$X$6 -> 0.016 | Y23: =IF(CO2_Calculator_Table[[#This Row],[Pre-carriage ROAD (km, if electric)]]=0,(O23*P23*V23),(O23*Q23*V23)) -> 58.08 | Z23: =O23*R23*W23 -> 720 | AA23: =O23*S23*X23 -> 0 | AB23: =O23*T23*V23 -> 4907.76 | AC23: =O23*U23*V23 -> 7913.4 | AD23: =Z23 -> 720 | AE23: =AA23 -> 0 | AF23: =Y23+AB23 -> 4965.84 | AG23: =AD23+AE23+AF23 -> 5685.84 | AH23: =SUM(U23)*V23*O23 -> 7913.4 | AI23: =AH23-AG23 -> 2227.56
E24: TURKEY | F24: GEBZE | G24: PL | H24: Olszowa | I24: PENDIK (TR) - TRIESTE (IT)-TURKEY-GEBZE-PL-Olszowa | J24: PENDIK (TR) - TRIESTE (IT) | N24: 24TON / 45HCPW BOX | O24: 24 | P24: =SUMIFS(ROUTES!H:H,ROUTES!B:B,CO2_Calculator_Table[[#This Row],[Route]],ROUTES!E:E,CO2_Calculator_Table[[#This Row],[Loading City]],ROUTES!G:G,CO2_Calculator_Table[[#This Row],[Unloading City]],ROUTES!C:C,CO2_Calculator_Table[[#This Row],[Route Detail]]) -> 20 | Q24: 0 | R24: =SUMIFS(ROUTES!I:I,ROUTES!B:B,CO2_Calculator_Table[[#This Row],[Route]],ROUTES!E:E,CO2_Calculator_Table[[#This Row],[Loading City]],ROUTES!G:G,CO2_Calculator_Table[[#This Row],[Unloading City]],ROUTES!C:C,CO2_Calculator_Table[[#This Row],[Route Detail]]) -> 2500 | S24: =SUMIFS(ROUTES!J:J,ROUTES!B:B,CO2_Calculator_Table[[#This Row],[Route]],ROUTES!E:E,CO2_Calculator_Table[[#This Row],[Loading City]],ROUTES!G:G,CO2_Calculator_Table[[#This Row],[Unloading City]],ROUTES!C:C,CO2_Calculator_Table[[#This Row],[Route Detail]]) -> 0 | T24: =SUMIFS(ROUTES!K:K,ROUTES!B:B,CO2_Calculator_Table[[#This Row],[Route]],ROUTES!E:E,CO2_Calculator_Table[[#This Row],[Loading City]],ROUTES!G:G,CO2_Calculator_Table[[#This Row],[Unloading City]],ROUTES!C:C,CO2_Calculator_Table[[#This Row],[Route Detail]]) -> 930 | U24: =SUMIFS(ROUTES!L:L,ROUTES!B:B,CO2_Calculator_Table[[#This Row],[Route]],ROUTES!E:E,CO2_Calculator_Table[[#This Row],[Loading City]],ROUTES!G:G,CO2_Calculator_Table[[#This Row],[Unloading City]],ROUTES!C:C,CO2_Calculator_Table[[#This Row],[Route Detail]]) -> 2200 | V24: =$V$6 -> 0.121 | W24: =$W$6 -> 0.012 | X24: =$X$6 -> 0.016 | Y24: =IF(CO2_Calculator_Table[[#This Row],[Pre-carriage ROAD (km, if electric)]]=0,(O24*P24*V24),(O24*Q24*V24)) -> 58.08 | Z24: =O24*R24*W24 -> 720 | AA24: =O24*S24*X24 -> 0 | AB24: =O24*T24*V24 -> 2700.72 | AC24: =O24*U24*V24 -> 6388.8 | AD24: =Z24 -> 720 | AE24: =AA24 -> 0 | AF24: =Y24+AB24 -> 2758.8 | AG24: =AD24+AE24+AF24 -> 3478.8 | AH24: =SUM(U24)*V24*O24 -> 6388.8 | AI24: =AH24-AG24 -> 2910
E25: PL | F25: 58-100 | G25: TURKEY | H25: GEBZE | I25: TRIESTE (IT) - PENDIK (TR)-PL-58-100-TURKEY-GEBZE | J25: TRIESTE (IT) - PENDIK (TR) | N25: 24TON / 45HCPW BOX | O25: 24 | P25: =SUMIFS(ROUTES!H:H,ROUTES!B:B,CO2_Calculator_Table[[#This Row],[Route]],ROUTES!E:E,CO2_Calculator_Table[[#This Row],[Loading City]],ROUTES!G:G,CO2_Calculator_Table[[#This Row],[Unloading City]],ROUTES!C:C,CO2_Calculator_Table[[#This Row],[Route Detail]]) -> 870 | Q25: 0 | R25: =SUMIFS(ROUTES!I:I,ROUTES!B:B,CO2_Calculator_Table[[#This Row],[Route]],ROUTES!E:E,CO2_Calculator_Table[[#This Row],[Loading City]],ROUTES!G:G,CO2_Calculator_Table[[#This Row],[Unloading City]],ROUTES!C:C,CO2_Calculator_Table[[#This Row],[Route Detail]]) -> 2500 | S25: =SUMIFS(ROUTES!J:J,ROUTES!B:B,CO2_Calculator_Table[[#This Row],[Route]],ROUTES!E:E,CO2_Calculator_Table[[#This Row],[Loading City]],ROUTES!G:G,CO2_Calculator_Table[[#This Row],[Unloading City]],ROUTES!C:C,CO2_Calculator_Table[[#This Row],[Route Detail]]) -> 0 | T25: =SUMIFS(ROUTES!K:K,ROUTES!B:B,CO2_Calculator_Table[[#This Row],[Route]],ROUTES!E:E,CO2_Calculator_Table[[#This Row],[Loading City]],ROUTES!G:G,CO2_Calculator_Table[[#This Row],[Unloading City]],ROUTES!C:C,CO2_Calculator_Table[[#This Row],[Route Detail]]) -> 20 | U25: =SUMIFS(ROUTES!L:L,ROUTES!B:B,CO2_Calculator_Table[[#This Row],[Route]],ROUTES!E:E,CO2_Calculator_Table[[#This Row],[Loading City]],ROUTES!G:G,CO2_Calculator_Table[[#This Row],[Unloading City]],ROUTES!C:C,CO2_Calculator_Table[[#This Row],[Route Detail]]) -> 1975 | V25: =$V$6 -> 0.121 | W25: =$W$6 -> 0.012 | X25: =$X$6 -> 0.016 | Y25: =IF(CO2_Calculator_Table[[#This Row],[Pre-carriage ROAD (km, if electric)]]=0,(O25*P25*V25),(O25*Q25*V25)) -> 2526.48 | Z25: =O25*R25*W25 -> 720 | AA25: =O25*S25*X25 -> 0 | AB25: =O25*T25*V25 -> 58.08 | AC25: =O25*U25*V25 -> 5735.4 | AD25: =Z25 -> 720 | AE25: =AA25 -> 0 | AF25: =Y25+AB25 -> 2584.56 | AG25: =AD25+AE25+AF25 -> 3304.56 | AH25: =SUM(U25)*V25*O25 -> 5735.4 | AI25: =AH25-AG25 -> 2430.84
E26: PL | F26: 58-100 | G26: TURKEY | H26: TUZLA | I26: TRIESTE (IT) - PENDIK (TR)-PL-58-100-TURKEY-TUZLA | J26: TRIESTE (IT) - PENDIK (TR) | N26: 24TON / 45HCPW BOX | O26: 24 | P26: =SUMIFS(ROUTES!H:H,ROUTES!B:B,CO2_Calculator_Table[[#This Row],[Route]],ROUTES!E:E,CO2_Calculator_Table[[#This Row],[Loading City]],ROUTES!G:G,CO2_Calculator_Table[[#This Row],[Unloading City]],ROUTES!C:C,CO2_Calculator_Table[[#This Row],[Route Detail]]) -> 870 | Q26: 0 | R26: =SUMIFS(ROUTES!I:I,ROUTES!B:B,CO2_Calculator_Table[[#This Row],[Route]],ROUTES!E:E,CO2_Calculator_Table[[#This Row],[Loading City]],ROUTES!G:G,CO2_Calculator_Table[[#This Row],[Unloading City]],ROUTES!C:C,CO2_Calculator_Table[[#This Row],[Route Detail]]) -> 2500 | S26: =SUMIFS(ROUTES!J:J,ROUTES!B:B,CO2_Calculator_Table[[#This Row],[Route]],ROUTES!E:E,CO2_Calculator_Table[[#This Row],[Loading City]],ROUTES!G:G,CO2_Calculator_Table[[#This Row],[Unloading City]],ROUTES!C:C,CO2_Calculator_Table[[#This Row],[Route Detail]]) -> 0 | T26: =SUMIFS(ROUTES!K:K,ROUTES!B:B,CO2_Calculator_Table[[#This Row],[Route]],ROUTES!E:E,CO2_Calculator_Table[[#This Row],[Loading City]],ROUTES!G:G,CO2_Calculator_Table[[#This Row],[Unloading City]],ROUTES!C:C,CO2_Calculator_Table[[#This Row],[Route Detail]]) -> 15 | U26: =SUMIFS(ROUTES!L:L,ROUTES!B:B,CO2_Calculator_Table[[#This Row],[Route]],ROUTES!E:E,CO2_Calculator_Table[[#This Row],[Loading City]],ROUTES!G:G,CO2_Calculator_Table[[#This Row],[Unloading City]],ROUTES!C:C,CO2_Calculator_Table[[#This Row],[Route Detail]]) -> 1955 | V26: =$V$6 -> 0.121 | W26: =$W$6 -> 0.012 | X26: =$X$6 -> 0.016 | Y26: =IF(CO2_Calculator_Table[[#This Row],[Pre-carriage ROAD (km, if electric)]]=0,(O26*P26*V26),(O26*Q26*V26)) -> 2526.48 | Z26: =O26*R26*W26 -> 720 | AA26: =O26*S26*X26 -> 0 | AB26: =O26*T26*V26 -> 43.56 | AC26: =O26*U26*V26 -> 5677.32 | AD26: =Z26 -> 720 | AE26: =AA26 -> 0 | AF26: =Y26+AB26 -> 2570.04 | AG26: =AD26+AE26+AF26 -> 3290.04 | AH26: =SUM(U26)*V26*O26 -> 5677.32 | AI26: =AH26-AG26 -> 2387.28
E27: PL | F27: 54-610 | G27: TURKEY | H27: GEBZE | I27: TRIESTE (IT) - PENDIK (TR)-PL-54-610-TURKEY-GEBZE | J27: TRIESTE (IT) - PENDIK (TR) | N27: 24TON / 45HCPW BOX | O27: 24 | P27: =SUMIFS(ROUTES!H:H,ROUTES!B:B,CO2_Calculator_Table[[#This Row],[Route]],ROUTES!E:E,CO2_Calculator_Table[[#This Row],[Loading City]],ROUTES!G:G,CO2_Calculator_Table[[#This Row],[Unloading City]],ROUTES!C:C,CO2_Calculator_Table[[#This Row],[Route Detail]]) -> 1010 | Q27: 0 | R27: =SUMIFS(ROUTES!I:I,ROUTES!B:B,CO2_Calculator_Table[[#This Row],[Route]],ROUTES!E:E,CO2_Calculator_Table[[#This Row],[Loading City]],ROUTES!G:G,CO2_Calculator_Table[[#This Row],[Unloading City]],ROUTES!C:C,CO2_Calculator_Table[[#This Row],[Route Detail]]) -> 2500 | S27: =SUMIFS(ROUTES!J:J,ROUTES!B:B,CO2_Calculator_Table[[#This Row],[Route]],ROUTES!E:E,CO2_Calculator_Table[[#This Row],[Loading City]],ROUTES!G:G,CO2_Calculator_Table[[#This Row],[Unloading City]],ROUTES!C:C,CO2_Calculator_Table[[#This Row],[Route Detail]]) -> 0 | T27: =SUMIFS(ROUTES!K:K,ROUTES!B:B,CO2_Calculator_Table[[#This Row],[Route]],ROUTES!E:E,CO2_Calculator_Table[[#This Row],[Loading City]],ROUTES!G:G,CO2_Calculator_Table[[#This Row],[Unloading City]],ROUTES!C:C,CO2_Calculator_Table[[#This Row],[Route Detail]]) -> 20 | U27: =SUMIFS(ROUTES!L:L,ROUTES!B:B,CO2_Calculator_Table[[#This Row],[Route]],ROUTES!E:E,CO2_Calculator_Table[[#This Row],[Loading City]],ROUTES!G:G,CO2_Calculator_Table[[#This Row],[Unloading City]],ROUTES!C:C,CO2_Calculator_Table[[#This Row],[Route Detail]]) -> 2120 | V27: =$V$6 -> 0.121 | W27: =$W$6 -> 0.012 | X27: =$X$6 -> 0.016 | Y27: =IF(CO2_Calculator_Table[[#This Row],[Pre-carriage ROAD (km, if electric)]]=0,(O27*P27*V27),(O27*Q27*V27)) -> 2933.04 | Z27: =O27*R27*W27 -> 720 | AA27: =O27*S27*X27 -> 0 | AB27: =O27*T27*V27 -> 58.08 | AC27: =O27*U27*V27 -> 6156.48 | AD27: =Z27 -> 720 | AE27: =AA27 -> 0 | AF27: =Y27+AB27 -> 2991.12 | AG27: =AD27+AE27+AF27 -> 3711.12 | AH27: =SUM(U27)*V27*O27 -> 6156.48 | AI27: =AH27-AG27 -> 2445.36
E28: TURKEY | F28: GEBZE | G28: Bosna | H28: Hadzici | I28: --TURKEY-GEBZE-Bosna-Hadzici | J28: - | N28: 24TON / 45HCPW BOX | O28: 24 | P28: =SUMIFS(ROUTES!H:H,ROUTES!B:B,CO2_Calculator_Table[[#This Row],[Route]],ROUTES!E:E,CO2_Calculator_Table[[#This Row],[Loading City]],ROUTES!G:G,CO2_Calculator_Table[[#This Row],[Unloading City]],ROUTES!C:C,CO2_Calculator_Table[[#This Row],[Route Detail]]) -> 0 | Q28: 0 | R28: =SUMIFS(ROUTES!I:I,ROUTES!B:B,CO2_Calculator_Table[[#This Row],[Route]],ROUTES!E:E,CO2_Calculator_Table[[#This Row],[Loading City]],ROUTES!G:G,CO2_Calculator_Table[[#This Row],[Unloading City]],ROUTES!C:C,CO2_Calculator_Table[[#This Row],[Route Detail]]) -> 0 | S28: =SUMIFS(ROUTES!J:J,ROUTES!B:B,CO2_Calculator_Table[[#This Row],[Route]],ROUTES!E:E,CO2_Calculator_Table[[#This Row],[Loading City]],ROUTES!G:G,CO2_Calculator_Table[[#This Row],[Unloading City]],ROUTES!C:C,CO2_Calculator_Table[[#This Row],[Route Detail]]) -> 0 | T28: =SUMIFS(ROUTES!K:K,ROUTES!B:B,CO2_Calculator_Table[[#This Row],[Route]],ROUTES!E:E,CO2_Calculator_Table[[#This Row],[Loading City]],ROUTES!G:G,CO2_Calculator_Table[[#This Row],[Unloading City]],ROUTES!C:C,CO2_Calculator_Table[[#This Row],[Route Detail]]) -> 0 | U28: =SUMIFS(ROUTES!L:L,ROUTES!B:B,CO2_Calculator_Table[[#This Row],[Route]],ROUTES!E:E,CO2_Calculator_Table[[#This Row],[Loading City]],ROUTES!G:G,CO2_Calculator_Table[[#This Row],[Unloading City]],ROUTES!C:C,CO2_Calculator_Table[[#This Row],[Route Detail]]) -> 1240 | V28: =$V$6 -> 0.121 | W28: =$W$6 -> 0.012 | X28: =$X$6 -> 0.016 | Y28: =IF(CO2_Calculator_Table[[#This Row],[Pre-carriage ROAD (km, if electric)]]=0,(O28*P28*V28),(O28*Q28*V28)) -> 0 | Z28: =O28*R28*W28 -> 0 | AA28: =O28*S28*X28 -> 0 | AB28: =O28*T28*V28 -> 0 | AC28: =O28*U28*V28 -> 3600.96 | AD28: =Z28 -> 0 | AE28: =AA28 -> 0 | AF28: =Y28+AB28 -> 0 | AG28: =AD28+AE28+AF28 -> 0 | AH28: =SUM(U28)*V28*O28 -> 3600.96 | AI28: =AH28-AG28 -> 3600.96
E29: TURKEY | F29: GEBZE | G29: Bulgaria | H29: Sofia | I29: --TURKEY-GEBZE-Bulgaria-Sofia | J29: - | N29: 24TON / 45HCPW BOX | O29: 24 | P29: =SUMIFS(ROUTES!H:H,ROUTES!B:B,CO2_Calculator_Table[[#This Row],[Route]],ROUTES!E:E,CO2_Calculator_Table[[#This Row],[Loading City]],ROUTES!G:G,CO2_Calculator_Table[[#This Row],[Unloading City]],ROUTES!C:C,CO2_Calculator_Table[[#This Row],[Route Detail]]) -> 0 | Q29: 0 | R29: =SUMIFS(ROUTES!I:I,ROUTES!B:B,CO2_Calculator_Table[[#This Row],[Route]],ROUTES!E:E,CO2_Calculator_Table[[#This Row],[Loading City]],ROUTES!G:G,CO2_Calculator_Table[[#This Row],[Unloading City]],ROUTES!C:C,CO2_Calculator_Table[[#This Row],[Route Detail]]) -> 0 | S29: =SUMIFS(ROUTES!J:J,ROUTES!B:B,CO2_Calculator_Table[[#This Row],[Route]],ROUTES!E:E,CO2_Calculator_Table[[#This Row],[Loading City]],ROUTES!G:G,CO2_Calculator_Table[[#This Row],[Unloading City]],ROUTES!C:C,CO2_Calculator_Table[[#This Row],[Route Detail]]) -> 0 | T29: =SUMIFS(ROUTES!K:K,ROUTES!B:B,CO2_Calculator_Table[[#This Row],[Route]],ROUTES!E:E,CO2_Calculator_Table[[#This Row],[Loading City]],ROUTES!G:G,CO2_Calculator_Table[[#This Row],[Unloading City]],ROUTES!C:C,CO2_Calculator_Table[[#This Row],[Route Detail]]) -> 0 | U29: =SUMIFS(ROUTES!L:L,ROUTES!B:B,CO2_Calculator_Table[[#This Row],[Route]],ROUTES!E:E,CO2_Calculator_Table[[#This Row],[Loading City]],ROUTES!G:G,CO2_Calculator_Table[[#This Row],[Unloading City]],ROUTES!C:C,CO2_Calculator_Table[[#This Row],[Route Detail]]) -> 625 | V29: =$V$6 -> 0.121 | W29: =$W$6 -> 0.012 | X29: =$X$6 -> 0.016 | Y29: =IF(CO2_Calculator_Table[[#This Row],[Pre-carriage ROAD (km, if electric)]]=0,(O29*P29*V29),(O29*Q29*V29)) -> 0 | Z29: =O29*R29*W29 -> 0 | AA29: =O29*S29*X29 -> 0 | AB29: =O29*T29*V29 -> 0 | AC29: =O29*U29*V29 -> 1815 | AD29: =Z29 -> 0 | AE29: =AA29 -> 0 | AF29: =Y29+AB29 -> 0 | AG29: =AD29+AE29+AF29 -> 0 | AH29: =SUM(U29)*V29*O29 -> 1815 | AI29: =AH29-AG29 -> 1815
E30: Turkey | F30: Gebze | G30: Kosovo | H30: Fushe Kosove | I30: --Turkey-Gebze-Kosovo-Fushe Kosove | J30: - | N30: 24TON / 45HCPW BOX | O30: 24 | P30: =SUMIFS(ROUTES!H:H,ROUTES!B:B,CO2_Calculator_Table[[#This Row],[Route]],ROUTES!E:E,CO2_Calculator_Table[[#This Row],[Loading City]],ROUTES!G:G,CO2_Calculator_Table[[#This Row],[Unloading City]],ROUTES!C:C,CO2_Calculator_Table[[#This Row],[Route Detail]]) -> 0 | Q30: 0 | R30: =SUMIFS(ROUTES!I:I,ROUTES!B:B,CO2_Calculator_Table[[#This Row],[Route]],ROUTES!E:E,CO2_Calculator_Table[[#This Row],[Loading City]],ROUTES!G:G,CO2_Calculator_Table[[#This Row],[Unloading City]],ROUTES!C:C,CO2_Calculator_Table[[#This Row],[Route Detail]]) -> 0 | S30: =SUMIFS(ROUTES!J:J,ROUTES!B:B,CO2_Calculator_Table[[#This Row],[Route]],ROUTES!E:E,CO2_Calculator_Table[[#This Row],[Loading City]],ROUTES!G:G,CO2_Calculator_Table[[#This Row],[Unloading City]],ROUTES!C:C,CO2_Calculator_Table[[#This Row],[Route Detail]]) -> 0 | T30: =SUMIFS(ROUTES!K:K,ROUTES!B:B,CO2_Calculator_Table[[#This Row],[Route]],ROUTES!E:E,CO2_Calculator_Table[[#This Row],[Loading City]],ROUTES!G:G,CO2_Calculator_Table[[#This Row],[Unloading City]],ROUTES!C:C,CO2_Calculator_Table[[#This Row],[Route Detail]]) -> 0 | U30: =SUMIFS(ROUTES!L:L,ROUTES!B:B,CO2_Calculator_Table[[#This Row],[Route]],ROUTES!E:E,CO2_Calculator_Table[[#This Row],[Loading City]],ROUTES!G:G,CO2_Calculator_Table[[#This Row],[Unloading City]],ROUTES!C:C,CO2_Calculator_Table[[#This Row],[Route Detail]]) -> 945 | V30: =$V$6 -> 0.121 | W30: =$W$6 -> 0.012 | X30: =$X$6 -> 0.016 | Y30: =IF(CO2_Calculator_Table[[#This Row],[Pre-carriage ROAD (km, if electric)]]=0,(O30*P30*V30),(O30*Q30*V30)) -> 0 | Z30: =O30*R30*W30 -> 0 | AA30: =O30*S30*X30 -> 0 | AB30: =O30*T30*V30 -> 0 | AC30: =O30*U30*V30 -> 2744.28 | AD30: =Z30 -> 0 | AE30: =AA30 -> 0 | AF30: =Y30+AB30 -> 0 | AG30: =AD30+AE30+AF30 -> 0 | AH30: =SUM(U30)*V30*O30 -> 2744.28 | AI30: =AH30-AG30 -> 2744.28
E31: Turkey | F31: Gebze | G31: Macedonia | H31: Petrovec | I31: --Turkey-Gebze-Macedonia-Petrovec | J31: - | N31: 24TON / 45HCPW BOX | O31: 24 | P31: =SUMIFS(ROUTES!H:H,ROUTES!B:B,CO2_Calculator_Table[[#This Row],[Route]],ROUTES!E:E,CO2_Calculator_Table[[#This Row],[Loading City]],ROUTES!G:G,CO2_Calculator_Table[[#This Row],[Unloading City]],ROUTES!C:C,CO2_Calculator_Table[[#This Row],[Route Detail]]) -> 0 | Q31: 0 | R31: =SUMIFS(ROUTES!I:I,ROUTES!B:B,CO2_Calculator_Table[[#This Row],[Route]],ROUTES!E:E,CO2_Calculator_Table[[#This Row],[Loading City]],ROUTES!G:G,CO2_Calculator_Table[[#This Row],[Unloading City]],ROUTES!C:C,CO2_Calculator_Table[[#This Row],[Route Detail]]) -> 0 | S31: =SUMIFS(ROUTES!J:J,ROUTES!B:B,CO2_Calculator_Table[[#This Row],[Route]],ROUTES!E:E,CO2_Calculator_Table[[#This Row],[Loading City]],ROUTES!G:G,CO2_Calculator_Table[[#This Row],[Unloading City]],ROUTES!C:C,CO2_Calculator_Table[[#This Row],[Route Detail]]) -> 0 | T31: =SUMIFS(ROUTES!K:K,ROUTES!B:B,CO2_Calculator_Table[[#This Row],[Route]],ROUTES!E:E,CO2_Calculator_Table[[#This Row],[Loading City]],ROUTES!G:G,CO2_Calculator_Table[[#This Row],[Unloading City]],ROUTES!C:C,CO2_Calculator_Table[[#This Row],[Route Detail]]) -> 0 | U31: =SUMIFS(ROUTES!L:L,ROUTES!B:B,CO2_Calculator_Table[[#This Row],[Route]],ROUTES!E:E,CO2_Calculator_Table[[#This Row],[Loading City]],ROUTES!G:G,CO2_Calculator_Table[[#This Row],[Unloading City]],ROUTES!C:C,CO2_Calculator_Table[[#This Row],[Route Detail]]) -> 870 | V31: =$V$6 -> 0.121 | W31: =$W$6 -> 0.012 | X31: =$X$6 -> 0.016 | Y31: =IF(CO2_Calculator_Table[[#This Row],[Pre-carriage ROAD (km, if electric)]]=0,(O31*P31*V31),(O31*Q31*V31)) -> 0 | Z31: =O31*R31*W31 -> 0 | AA31: =O31*S31*X31 -> 0 | AB31: =O31*T31*V31 -> 0 | AC31: =O31*U31*V31 -> 2526.48 | AD31: =Z31 -> 0 | AE31: =AA31 -> 0 | AF31: =Y31+AB31 -> 0 | AG31: =AD31+AE31+AF31 -> 0 | AH31: =SUM(U31)*V31*O31 -> 2526.48 | AI31: =AH31-AG31 -> 2526.48
E32: Turkey | F32: Gebze | G32: Montenegro | H32: Kotor | I32: --Turkey-Gebze-Montenegro-Kotor | J32: - | N32: 24TON / 45HCPW BOX | O32: 24 | P32: =SUMIFS(ROUTES!H:H,ROUTES!B:B,CO2_Calculator_Table[[#This Row],[Route]],ROUTES!E:E,CO2_Calculator_Table[[#This Row],[Loading City]],ROUTES!G:G,CO2_Calculator_Table[[#This Row],[Unloading City]],ROUTES!C:C,CO2_Calculator_Table[[#This Row],[Route Detail]]) -> 0 | Q32: 0 | R32: =SUMIFS(ROUTES!I:I,ROUTES!B:B,CO2_Calculator_Table[[#This Row],[Route]],ROUTES!E:E,CO2_Calculator_Table[[#This Row],[Loading City]],ROUTES!G:G,CO2_Calculator_Table[[#This Row],[Unloading City]],ROUTES!C:C,CO2_Calculator_Table[[#This Row],[Route Detail]]) -> 0 | S32: =SUMIFS(ROUTES!J:J,ROUTES!B:B,CO2_Calculator_Table[[#This Row],[Route]],ROUTES!E:E,CO2_Calculator_Table[[#This Row],[Loading City]],ROUTES!G:G,CO2_Calculator_Table[[#This Row],[Unloading City]],ROUTES!C:C,CO2_Calculator_Table[[#This Row],[Route Detail]]) -> 0 | T32: =SUMIFS(ROUTES!K:K,ROUTES!B:B,CO2_Calculator_Table[[#This Row],[Route]],ROUTES!E:E,CO2_Calculator_Table[[#This Row],[Loading City]],ROUTES!G:G,CO2_Calculator_Table[[#This Row],[Unloading City]],ROUTES!C:C,CO2_Calculator_Table[[#This Row],[Route Detail]]) -> 0 | U32: =SUMIFS(ROUTES!L:L,ROUTES!B:B,CO2_Calculator_Table[[#This Row],[Route]],ROUTES!E:E,CO2_Calculator_Table[[#This Row],[Loading City]],ROUTES!G:G,CO2_Calculator_Table[[#This Row],[Unloading City]],ROUTES!C:C,CO2_Calculator_Table[[#This Row],[Route Detail]]) -> 1240 | V32: =$V$6 -> 0.121 | W32: =$W$6 -> 0.012 | X32: =$X$6 -> 0.016 | Y32: =IF(CO2_Calculator_Table[[#This Row],[Pre-carriage ROAD (km, if electric)]]=0,(O32*P32*V32),(O32*Q32*V32)) -> 0 | Z32: =O32*R32*W32 -> 0 | AA32: =O32*S32*X32 -> 0 | AB32: =O32*T32*V32 -> 0 | AC32: =O32*U32*V32 -> 3600.96 | AD32: =Z32 -> 0 | AE32: =AA32 -> 0 | AF32: =Y32+AB32 -> 0 | AG32: =AD32+AE32+AF32 -> 0 | AH32: =SUM(U32)*V32*O32 -> 3600.96 | AI32: =AH32-AG32 -> 3600.96
A33: é | E33: Turkey | F33: Gebze | G33: Romania | H33: Joita | I33: --Turkey-Gebze-Romania-Joita | J33: - | N33: 24TON / 45HCPW BOX | O33: 24 | P33: =SUMIFS(ROUTES!H:H,ROUTES!B:B,CO2_Calculator_Table[[#This Row],[Route]],ROUTES!E:E,CO2_Calculator_Table[[#This Row],[Loading City]],ROUTES!G:G,CO2_Calculator_Table[[#This Row],[Unloading City]],ROUTES!C:C,CO2_Calculator_Table[[#This Row],[Route Detail]]) -> 0 | Q33: 0 | R33: =SUMIFS(ROUTES!I:I,ROUTES!B:B,CO2_Calculator_Table[[#This Row],[Route]],ROUTES!E:E,CO2_Calculator_Table[[#This Row],[Loading City]],ROUTES!G:G,CO2_Calculator_Table[[#This Row],[Unloading City]],ROUTES!C:C,CO2_Calculator_Table[[#This Row],[Route Detail]]) -> 0 | S33: =SUMIFS(ROUTES!J:J,ROUTES!B:B,CO2_Calculator_Table[[#This Row],[Route]],ROUTES!E:E,CO2_Calculator_Table[[#This Row],[Loading City]],ROUTES!G:G,CO2_Calculator_Table[[#This Row],[Unloading City]],ROUTES!C:C,CO2_Calculator_Table[[#This Row],[Route Detail]]) -> 0 | T33: =SUMIFS(ROUTES!K:K,ROUTES!B:B,CO2_Calculator_Table[[#This Row],[Route]],ROUTES!E:E,CO2_Calculator_Table[[#This Row],[Loading City]],ROUTES!G:G,CO2_Calculator_Table[[#This Row],[Unloading City]],ROUTES!C:C,CO2_Calculator_Table[[#This Row],[Route Detail]]) -> 0 | U33: =SUMIFS(ROUTES!L:L,ROUTES!B:B,CO2_Calculator_Table[[#This Row],[Route]],ROUTES!E:E,CO2_Calculator_Table[[#This Row],[Loading City]],ROUTES!G:G,CO2_Calculator_Table[[#This Row],[Unloading City]],ROUTES!C:C,CO2_Calculator_Table[[#This Row],[Route Detail]]) -> 730 | V33: =$V$6 -> 0.121 | W33: =$W$6 -> 0.012 | X33: =$X$6 -> 0.016 | Y33: =IF(CO2_Calculator_Table[[#This Row],[Pre-carriage ROAD (km, if electric)]]=0,(O33*P33*V33),(O33*Q33*V33)) -> 0 | Z33: =O33*R33*W33 -> 0 | AA33: =O33*S33*X33 -> 0 | AB33: =O33*T33*V33 -> 0 | AC33: =O33*U33*V33 -> 2119.92 | AD33: =Z33 -> 0 | AE33: =AA33 -> 0 | AF33: =Y33+AB33 -> 0 | AG33: =AD33+AE33+AF33 -> 0 | AH33: =SUM(U33)*V33*O33 -> 2119.92 | AI33: =AH33-AG33 -> 2119.92
E34: Turkey | F34: Gebze | G34: Serbia | H34: Zemun | I34: --Turkey-Gebze-Serbia-Zemun | J34: - | N34: 24TON / 45HCPW BOX | O34: 24 | P34: =SUMIFS(ROUTES!H:H,ROUTES!B:B,CO2_Calculator_Table[[#This Row],[Route]],ROUTES!E:E,CO2_Calculator_Table[[#This Row],[Loading City]],ROUTES!G:G,CO2_Calculator_Table[[#This Row],[Unloading City]],ROUTES!C:C,CO2_Calculator_Table[[#This Row],[Route Detail]]) -> 0 | Q34: 0 | R34: =SUMIFS(ROUTES!I:I,ROUTES!B:B,CO2_Calculator_Table[[#This Row],[Route]],ROUTES!E:E,CO2_Calculator_Table[[#This Row],[Loading City]],ROUTES!G:G,CO2_Calculator_Table[[#This Row],[Unloading City]],ROUTES!C:C,CO2_Calculator_Table[[#This Row],[Route Detail]]) -> 0 | S34: =SUMIFS(ROUTES!J:J,ROUTES!B:B,CO2_Calculator_Table[[#This Row],[Route]],ROUTES!E:E,CO2_Calculator_Table[[#This Row],[Loading City]],ROUTES!G:G,CO2_Calculator_Table[[#This Row],[Unloading City]],ROUTES!C:C,CO2_Calculator_Table[[#This Row],[Route Detail]]) -> 0 | T34: =SUMIFS(ROUTES!K:K,ROUTES!B:B,CO2_Calculator_Table[[#This Row],[Route]],ROUTES!E:E,CO2_Calculator_Table[[#This Row],[Loading City]],ROUTES!G:G,CO2_Calculator_Table[[#This Row],[Unloading City]],ROUTES!C:C,CO2_Calculator_Table[[#This Row],[Route Detail]]) -> 0 | U34: =SUMIFS(ROUTES!L:L,ROUTES!B:B,CO2_Calculator_Table[[#This Row],[Route]],ROUTES!E:E,CO2_Calculator_Table[[#This Row],[Loading City]],ROUTES!G:G,CO2_Calculator_Table[[#This Row],[Unloading City]],ROUTES!C:C,CO2_Calculator_Table[[#This Row],[Route Detail]]) -> 1040 | V34: =$V$6 -> 0.121 | W34: =$W$6 -> 0.012 | X34: =$X$6 -> 0.016 | Y34: =IF(CO2_Calculator_Table[[#This Row],[Pre-carriage ROAD (km, if electric)]]=0,(O34*P34*V34),(O34*Q34*V34)) -> 0 | Z34: =O34*R34*W34 -> 0 | AA34: =O34*S34*X34 -> 0 | AB34: =O34*T34*V34 -> 0 | AC34: =O34*U34*V34 -> 3020.16 | AD34: =Z34 -> 0 | AE34: =AA34 -> 0 | AF34: =Y34+AB34 -> 0 | AG34: =AD34+AE34+AF34 -> 0 | AH34: =SUM(U34)*V34*O34 -> 3020.16 | AI34: =AH34-AG34 -> 3020.16
E35: Poland | F35: Swidnica | G35: Romania | H35: Joita | I35: --Poland-Swidnica-Romania-Joita | J35: - | N35: 24TON / 45HCPW BOX | O35: 24 | P35: =SUMIFS(ROUTES!H:H,ROUTES!B:B,CO2_Calculator_Table[[#This Row],[Route]],ROUTES!E:E,CO2_Calculator_Table[[#This Row],[Loading City]],ROUTES!G:G,CO2_Calculator_Table[[#This Row],[Unloading City]],ROUTES!C:C,CO2_Calculator_Table[[#This Row],[Route Detail]]) -> 0 | Q35: 0 | R35: =SUMIFS(ROUTES!I:I,ROUTES!B:B,CO2_Calculator_Table[[#This Row],[Route]],ROUTES!E:E,CO2_Calculator_Table[[#This Row],[Loading City]],ROUTES!G:G,CO2_Calculator_Table[[#This Row],[Unloading City]],ROUTES!C:C,CO2_Calculator_Table[[#This Row],[Route Detail]]) -> 0 | S35: =SUMIFS(ROUTES!J:J,ROUTES!B:B,CO2_Calculator_Table[[#This Row],[Route]],ROUTES!E:E,CO2_Calculator_Table[[#This Row],[Loading City]],ROUTES!G:G,CO2_Calculator_Table[[#This Row],[Unloading City]],ROUTES!C:C,CO2_Calculator_Table[[#This Row],[Route Detail]]) -> 0 | T35: =SUMIFS(ROUTES!K:K,ROUTES!B:B,CO2_Calculator_Table[[#This Row],[Route]],ROUTES!E:E,CO2_Calculator_Table[[#This Row],[Loading City]],ROUTES!G:G,CO2_Calculator_Table[[#This Row],[Unloading City]],ROUTES!C:C,CO2_Calculator_Table[[#This Row],[Route Detail]]) -> 0 | U35: =SUMIFS(ROUTES!L:L,ROUTES!B:B,CO2_Calculator_Table[[#This Row],[Route]],ROUTES!E:E,CO2_Calculator_Table[[#This Row],[Loading City]],ROUTES!G:G,CO2_Calculator_Table[[#This Row],[Unloading City]],ROUTES!C:C,CO2_Calculator_Table[[#This Row],[Route Detail]]) -> 1390 | V35: =$V$6 -> 0.121 | W35: =$W$6 -> 0.012 | X35: =$X$6 -> 0.016 | Y35: =IF(CO2_Calculator_Table[[#This Row],[Pre-carriage ROAD (km, if electric)]]=0,(O35*P35*V35),(O35*Q35*V35)) -> 0 | Z35: =O35*R35*W35 -> 0 | AA35: =O35*S35*X35 -> 0 | AB35: =O35*T35*V35 -> 0 | AC35: =O35*U35*V35 -> 4036.56 | AD35: =Z35 -> 0 | AE35: =AA35 -> 0 | AF35: =Y35+AB35 -> 0 | AG35: =AD35+AE35+AF35 -> 0 | AH35: =SUM(U35)*V35*O35 -> 4036.56 | AI35: =AH35-AG35 -> 4036.56
